<?xml version="1.0" ?>
<!-- =================================================================================== -->
<!-- |    This document was autogenerated by xacro from panda_arm_hand.urdf.xacro      | -->
<!-- |    EDITING THIS FILE BY HAND IS NOT RECOMMENDED                                 | -->
<!-- =================================================================================== -->
<robot name="panda" xmlns:xacro="http://www.ros.org/wiki/xacro">
  <link name="panda_link0">
  	<inertial>
      <origin rpy="0 0 0" xyz="0 0 0.05"/>
       <mass value="2.9"/>
       <inertia ixx="0.1" ixy="0" ixz="0" iyy="0.1" iyz="0" izz="0.1"/>
    </inertial>
    <visual>
      <geometry>
        <mesh filename="package://meshes/collision/link0.obj"/>
      </geometry>
      <material name="panda_white">
    		<color rgba="1. 1. 1. 1."/>
  		</material>
    </visual>
    <collision>
      <geometry>
        <mesh filename="package://meshes/collision/link0.obj"/>
      </geometry>
      <material name="panda_white"/>
    </collision>
  </link>
  <link name="panda_link1">
  	<inertial>
      <origin rpy="0 0 0" xyz="0 -0.04 -0.05"/>
       <mass value="2.7"/>
       <inertia ixx="0.1" ixy="0" ixz="0" iyy="0.1" iyz="0" izz="0.1"/>
    </inertial>
    <visual>
      <geometry>
        <mesh filename="package://meshes/visual/link1.obj"/>
      </geometry>
      <material name="panda_white"/>
    </visual>
    <collision>
      <geometry>
        <mesh filename="package://meshes/collision/link1.obj"/>
      </geometry>
      <material name="panda_white"/>
    </collision>
  </link>
  <joint name="panda_joint1" type="revolute">
    <safety_controller k_position="100.0" k_velocity="40.0" soft_lower_limit="-2.8973" soft_upper_limit="2.8973"/>
    <origin rpy="0 0 0" xyz="0 0 0.333"/>
    <parent link="panda_link0"/>
    <child link="panda_link1"/>
    <axis xyz="0 0 1"/>
    <limit effort="87" lower="-2.9671" upper="2.9671" velocity="2.1750"/>
  </joint>
  <link name="panda_link2">
  	<inertial>
      <origin rpy="0 0 0" xyz="0 -0.04 0.06"/>
       <mass value="2.73"/>
       <inertia ixx="0.1" ixy="0" ixz="0" iyy="0.1" iyz="0" izz="0.1"/>
    </inertial>
    <visual>
      <geometry>
        <mesh filename="package://meshes/visual/link2.obj"/>
      </geometry>
      <material name="panda_white"/>
    </visual>
    <collision>
      <geometry>
        <mesh filename="package://meshes/collision/link2.obj"/>
      </geometry>
      <material name="panda_white"/>
    </collision>
  </link>
  <joint name="panda_joint2" type="revolute">
    <safety_controller k_position="100.0" k_velocity="40.0" soft_lower_limit="-1.7628" soft_upper_limit="1.7628"/>
    <origin rpy="-1.57079632679 0 0" xyz="0 0 0"/>
    <parent link="panda_link1"/>
    <child link="panda_link2"/>
    <axis xyz="0 0 1"/>
    <limit effort="87" lower="-1.8326" upper="1.8326" velocity="2.1750"/>
  </joint>
  <link name="panda_link3">
	  <inertial>
      <origin rpy="0 0 0" xyz="0.01 0.01 -0.05"/>
       <mass value="2.04"/>
       <inertia ixx="0.1" ixy="0" ixz="0" iyy="0.1" iyz="0" izz="0.1"/>
    </inertial>
    <visual>
      <geometry>
        <mesh filename="package://meshes/visual/link3.obj"/>
      </geometry>
      <material name="panda_red">
    		<color rgba="1. 1. 1. 1."/>
  		</material>
    </visual>
    <collision>
      <geometry>
        <mesh filename="package://meshes/collision/link3.obj"/>
      </geometry>
    </collision>
  </link>
  <joint name="panda_joint3" type="revolute">
    <safety_controller k_position="100.0" k_velocity="40.0" soft_lower_limit="-2.8973" soft_upper_limit="2.8973"/>
    <origin rpy="1.57079632679 0 0" xyz="0 -0.316 0"/>
    <parent link="panda_link2"/>
    <child link="panda_link3"/>
    <axis xyz="0 0 1"/>
    <limit effort="87" lower="-2.9671" upper="2.9671" velocity="2.1750"/>
  </joint>
  <link name="panda_link4">
  	<inertial>
      <origin rpy="0 0 0" xyz="-0.03 0.03 0.02"/>
       <mass value="2.08"/>
       <inertia ixx="0.1" ixy="0" ixz="0" iyy="0.1" iyz="0" izz="0.1"/>
    </inertial>
    <visual>
      <geometry>
        <mesh filename="package://meshes/visual/link4.obj"/>
      </geometry>
      <material name="panda_white"/>
    </visual>
    <collision>
      <geometry>
        <mesh filename="package://meshes/collision/link4.obj"/>
      </geometry>
      <material name="panda_white"/>
    </collision>
  </link>
  <joint name="panda_joint4" type="revolute">
    <safety_controller k_position="100.0" k_velocity="40.0" soft_lower_limit="-3.0718" soft_upper_limit="-0.0698"/>
    <origin rpy="1.57079632679 0 0" xyz="0.0825 0 0"/>
    <parent link="panda_link3"/>
    <child link="panda_link4"/>
    <axis xyz="0 0 1"/>
    <limit effort="87" lower="-3.1416" upper="0.0" velocity="2.1750"/>
  </joint>
  <link name="panda_link5">
  	<inertial>
      <origin rpy="0 0 0" xyz="0 0.04 -0.12"/>
       <mass value="3"/>
       <inertia ixx="0.1" ixy="0" ixz="0" iyy="0.1" iyz="0" izz="0.1"/>
    </inertial>
    <visual>
      <geometry>
        <mesh filename="package://meshes/visual/link5.obj"/>
      </geometry>
      <material name="panda_white"/>
    </visual>
    <collision>
      <geometry>
        <mesh filename="package://meshes/collision/link5.obj"/>
      </geometry>
      <material name="panda_white"/>
    </collision>
  </link>
  <joint name="panda_joint5" type="revolute">
    <safety_controller k_position="100.0" k_velocity="40.0" soft_lower_limit="-2.8973" soft_upper_limit="2.8973"/>
    <origin rpy="-1.57079632679 0 0" xyz="-0.0825 0.384 0"/>
    <parent link="panda_link4"/>
    <child link="panda_link5"/>
    <axis xyz="0 0 1"/>
    <limit effort="12" lower="-2.9671" upper="2.9671" velocity="2.6100"/>
  </joint>
  <link name="panda_link6">
  	<inertial>
      <origin rpy="0 0 0" xyz="0.04 0 0"/>
       <mass value="1.3"/>
       <inertia ixx="0.1" ixy="0" ixz="0" iyy="0.1" iyz="0" izz="0.1"/>
    </inertial>
    <visual>
      <geometry>
        <mesh filename="package://meshes/visual/link6.obj"/>
      </geometry>
      <material name="panda_white"/>
    </visual>
    <collision>
      <geometry>
        <mesh filename="package://meshes/collision/link6.obj"/>
      </geometry>
      <material name="panda_white"/>
    </collision>
  </link>
  <joint name="panda_joint6" type="revolute">
    <safety_controller k_position="100.0" k_velocity="40.0" soft_lower_limit="-0.0175" soft_upper_limit="3.7525"/>
    <origin rpy="1.57079632679 0 0" xyz="0 0 0"/>
    <parent link="panda_link5"/>
    <child link="panda_link6"/>
    <axis xyz="0 0 1"/>
    <limit effort="12" lower="-0.0873" upper="3.8223" velocity="2.6100"/>
  </joint>
  <link name="panda_link7">
  	<inertial>
      <origin rpy="0 0 0" xyz="0 0 0.08"/>
       <mass value=".2"/>
       <inertia ixx="0.1" ixy="0" ixz="0" iyy="0.1" iyz="0" izz="0.1"/>
    </inertial>
    <visual>
      <geometry>
        <mesh filename="package://meshes/collision/link7.obj"/>
      </geometry>
      <material name="panda_white"/>
    </visual>
    <collision>
      <geometry>
        <mesh filename="package://meshes/collision/link7.obj"/>
      </geometry>
      <material name="panda_white"/>
    </collision>
  </link>
  <joint name="panda_joint7" type="revolute">
    <safety_controller k_position="100.0" k_velocity="40.0" soft_lower_limit="-2.8973" soft_upper_limit="2.8973"/>
    <origin rpy="1.57079632679 0 0" xyz="0.088 0 0"/>
    <parent link="panda_link6"/>
    <child link="panda_link7"/>
    <axis xyz="0 0 1"/>
    <limit effort="12" lower="-2.9671" upper="2.9671" velocity="2.6100"/>
  </joint>
  <link name="panda_link8">
  	 <inertial>
      <origin rpy="0 0 0" xyz="0 0 0"/>
       <mass value="0.0"/>
       <inertia ixx="0.1" ixy="0" ixz="0" iyy="0.1" iyz="0" izz="0.1"/>
    </inertial>
  </link>
  <joint name="panda_joint8" type="fixed">
    <origin rpy="0 0 0" xyz="0 0 0.107"/>
    <parent link="panda_link7"/>
    <child link="panda_link8"/>
    <axis xyz="0 0 0"/>
  </joint>
  
  <joint name="panda_hand_joint" type="fixed">
    <parent link="panda_link8"/>
    <child link="gripper_base_link"/>
    <origin rpy="0 0 3.9269908169872414" xyz="0 0 0"/>
  </joint>

  



  <!-- <link name="panda_hand">
  	<inertial>
      <origin rpy="0 0 0" xyz="0 0 0.04"/>
       <mass value=".81"/>
       <inertia ixx="0.1" ixy="0" ixz="0" iyy="0.1" iyz="0" izz="0.1"/>
    </inertial>
    <visual>
      <geometry>
        <mesh filename="package://meshes/visual/hand.obj"/>
      </geometry>
      <material name="panda_white"/>
    </visual>
    <collision>
      <geometry>
        <mesh filename="package://meshes/collision/hand.obj"/>
      </geometry>
      <material name="panda_white"/>
    </collision>
  </link> -->

  <!-- Weiss Gripper WSG50 -->

  <!-- ============================================================================= -->

  <!-- Weiss Gripper WSG50 -->

  <!-- ============================================================================= -->

  <!-- BASE LINK -->
  <link name="gripper_base_link">
      <inertial>
          <mass value="1.2" />
          <origin xyz="0 0 0" />
        <!--inertia ixx="1.0" ixy="0.0" ixz="0.0"
               iyy="100.0" iyz="0.0" 
               izz="1.0" /-->
          <inertia  ixx="1.0" ixy="0.0"  ixz="0.0"  iyy="1.0"  iyz="0.0"  izz="1.0" />
      </inertial>

      <visual>
          <origin xyz="0.0 0 0" rpy="0 0 0" />
          <geometry>
             <mesh filename="package://wsg50/WSG50_110.stl" scale="1 1 1"/>
       <!--box size="0.146 0.05 0.0735"/-->
          </geometry>
          <material name="grey">
            <color rgba="0.5 0.5 0.5 1"/>
          </material>
      </visual>

      <collision>
          <origin xyz="0.0 0 0" rpy="0 0 0" />
          <geometry>
       <!--box size="0.146 0.05 0.0735"/-->
             <mesh filename="package://wsg50/WSG50_110.stl" scale="1 1 1"/>
         </geometry>
     </collision>
  </link>


  <gazebo reference="gripper_base_link">
    <material>Gazebo/Grey</material>
    <turnGravityOff>false</turnGravityOff>
  </gazebo>

  <!-- GRIPPER LEFT -->

  <joint name="base_joint_gripper_left" type="prismatic">
     <limit lower="-0.055" upper="-0.0027" effort="1.0" velocity="1.0"/>
     <origin xyz="0 0 0" rpy="0 0 0" />      <!--origin xyz="-0.0067 0 0.049" rpy="0 0 0" /-->
     <parent link="gripper_base_link"/>
     <child link="gripper_left" />
     <dynamics friction="100" damping="100" />
     <axis xyz="1 0 0"/>
     <limit effort="100" velocity="100"/>
  </joint>

  <transmission name="base_trans_left" type="pr2_mechanism_model/SimpleTransmission">
     <actuator name="base_motor_left" />
     <joint name="base_joint_gripper_left" />
     <mechanicalReduction>1</mechanicalReduction>
     <motorTorqueConstant>1</motorTorqueConstant>
  </transmission>

  <link name="gripper_left">
      <inertial>
          <mass value="0.1" />
          <origin xyz="0 0 0" />
      <inertia ixx="1.0" ixy="0.0" ixz="0.0"
               iyy="1.0" iyz="0.0" 
               izz="1.0" />
      </inertial>

      <visual>
          <origin xyz="0.0 0 0" rpy="0 0 0" />
          <geometry>
             <mesh filename="package://wsg50/GUIDE_WSG50_110.stl" scale="0.001 0.001 0.001"/>
       <!--box size="0.0175 0.03 0.024"/-->
          </geometry>
          <material name="white">
            <color rgba="1. 1. 1. 1"/>
          </material>
      </visual>

      <collision>
          <origin xyz="0 0 0" rpy="0 0 0" />
          <geometry>
       <!--box size="0.0175 0.03 0.024"/-->
             <mesh filename="package://wsg50/GUIDE_WSG50_110.stl" scale="0.001 0.001 0.001"/>
         </geometry>
     </collision>
  </link>

  <gazebo reference="gripper_left">
    <material>Gazebo/Blue</material>
    <turnGravityOff>false</turnGravityOff>
  </gazebo>


  <!-- LEFT FINGER -->

  <joint name="guide_joint_finger_left" type="fixed">
     <origin xyz="0 0 0.023" rpy="0 0 0" />
     <parent link="gripper_left"/>
     <child link="finger_left" />
     <dynamics friction="100" damping="100" />
     <axis xyz="1 0 0"/>
     <limit effort="100" velocity="100"/>
  </joint>

  <link name="finger_left">

      <contact>
        <lateral_friction value="1"/>
        <rolling_friction value="0.1"/>
        <contact_cfm value="0.0"/>
        <contact_erp value="1.0"/>
      </contact>

      <inertial>
          <mass value="0.1" />
          <origin xyz="0 0 0" />
      <inertia ixx="1.0" ixy="0.0" ixz="0.0"
               iyy="1.0" iyz="0.0" 
               izz="1.0" />
      </inertial>

      <visual>
          <origin xyz="0.003 0.015 0.057" rpy="1.57 0 -1.57" />
          <geometry>
             <mesh filename="package://wsg50/DIGIT-WSG-50-V1.STL" scale="0.001 0.001 0.001"/>
          </geometry>
          <material name="white">
            <color rgba="1. 1. 1. 1"/>
          </material>
      </visual>

      <collision>
          <origin xyz="0.003 0.015 0.057" rpy="1.57 0 -1.57" />
          <geometry>
             <mesh filename="package://wsg50/DIGIT-WSG-50-V1.STL" scale="0.001 0.001 0.001"/>
         </geometry>
     </collision>
  </link>

  <gazebo reference="finger_left">
    <material>Gazebo/Blue</material>
    <turnGravityOff>false</turnGravityOff>
  </gazebo>


  <joint name="joint_finger_tip_left" type="fixed">
     <!-- <origin xyz="0 0 0.023" rpy="0 0 0" /> -->
     <origin xyz="-0.006 0 0.08" rpy="0 0 0" />
     <parent link="finger_left"/>
     <child link="finger_left_tip" />
     <dynamics friction="100" damping="100" />
     <axis xyz="1 0 0"/>
     <limit effort="100" velocity="100"/>
  </joint>

  <link name="finger_left_tip">

      <contact>
        <lateral_friction value="1"/>
        <rolling_friction value="0.1"/>
        <contact_cfm value="0.0"/>
        <contact_erp value="1.0"/>
      </contact>

      <inertial>
          <mass value="0.1" />
          <origin xyz="0 0 0" />
      <inertia ixx="1.0" ixy="0.0" ixz="0.0"
               iyy="1.0" iyz="0.0" 
               izz="1.0" />
      </inertial>

      <visual>
          <!-- <origin xyz="-0.006 0 0.057" rpy="0 0 0" /> -->
          <geometry>
             <mesh filename="package://wsg50/digit.STL"/>
          </geometry>
          <material name="white">
            <color rgba="1. 1. 1. 1"/>
          </material>
      </visual>

      <collision>
          <!-- <origin xyz="-0.006 0 0.057" rpy="0 0 0" /> -->
          <geometry>
             <mesh filename="package://wsg50/digit.STL"/>
         </geometry>
     </collision>
  </link>

  <!-- GRIPPER RIGHT -->

  <joint name="base_joint_gripper_right" type="prismatic">
     <limit lower="0.0027" upper="0.055" effort="1.0" velocity="1.0"/>
     <origin xyz="0 0 0" rpy="0 0 3.14159" />
     <parent link="gripper_base_link"/>
     <child link="gripper_right" />
     <axis xyz="-1 0 0"/>
     <dynamics friction="100" damping="100" />
     <limit effort="100" velocity="100"/>
  </joint>

  <transmission name="base_trans_right" type="pr2_mechanism_model/SimpleTransmission">
     <actuator name="base_motor_right" />
     <joint name="base_joint_gripper_right" />
     <mechanicalReduction>1</mechanicalReduction>
     <motorTorqueConstant>1</motorTorqueConstant>
  </transmission>
  
    <link name="gripper_right">
      <inertial>
          <mass value="0.1" />
          <origin xyz="0 0 0" />
      <inertia ixx="1.0" ixy="0.0" ixz="0.0"
               iyy="1.0" iyz="0.0" 
               izz="1.0" />
      </inertial>

      <visual>
          <origin xyz="0.0 0 0" rpy="0 0 0" />
          <geometry>
             <mesh filename="package://wsg50/GUIDE_WSG50_110.stl" scale="0.001 0.001 0.001"/>
       <!--box size="0.0175 0.03 0.024"/-->
          </geometry>
          <material name="white">
            <color rgba="1. 1. 1. 1"/>
          </material>
      </visual>

      <collision>
          <origin xyz="0 0 0" rpy="0 0 0" />
          <geometry>
       <!--box size="0.0175 0.03 0.024"/-->
             <mesh filename="package://wsg50/GUIDE_WSG50_110.stl" scale="0.001 0.001 0.001"/>
         </geometry>
     </collision>
  </link>

  <gazebo reference="gripper_right">
    <material>Gazebo/White</material>
    <turnGravityOff>false</turnGravityOff>
  </gazebo>

  <!-- RIGHT FINGER -->

  <joint name="guide_joint_finger_right" type="fixed">
     <origin xyz="0 0 0.023" rpy="0 0 0" />
     <parent link="gripper_right"/>
     <child link="finger_right" />
     <dynamics friction="100" damping="100" />
     <axis xyz="1 0 0"/>
     <limit effort="100" velocity="100"/>
  </joint>

  <link name="finger_right">

      <contact>
        <friction_anchor/>
        <stiffness value="30000.0"/>
        <damping value="1000.0"/>
        <lateral_friction value="1"/>
        <rolling_friction value="0.1"/>
        <contact_cfm value="0.0"/>
        <contact_erp value="1.0"/>
      </contact>

      <inertial>
          <mass value="0.1" />
          <origin xyz="0 0 0" />
      <inertia ixx="1.0" ixy="0.0" ixz="0.0"
               iyy="1.0" iyz="0.0" 
               izz="1.0" />
      </inertial>

      <visual>
          <origin xyz="0.003 0.015 0.057" rpy="1.57 0 -1.57" />
          <geometry>
             <mesh filename="package://wsg50/DIGIT-WSG-50-V1.STL" scale="0.001 0.001 0.001"/>
          </geometry>
          <material name="white">
            <color rgba="1. 1. 1. 1"/>
          </material>
      </visual>

      <collision>
          <origin xyz="0.003 0.015 0.057" rpy="1.57 0 -1.57" />
          <geometry>
             <mesh filename="package://wsg50/DIGIT-WSG-50-V1.STL" scale="0.001 0.001 0.001"/>
         </geometry>
     </collision>
  </link>

  <joint name="joint_finger_tip_right" type="fixed">

      <origin xyz="-0.006 0 0.08" rpy="0 0 0" />
     <!-- <origin xyz="0 0 0.023" rpy="0 0 0" /> -->
     <parent link="finger_right"/>
     <child link="finger_right_tip" />
     <dynamics friction="100" damping="100" />
     <axis xyz="1 0 0"/>
     <limit effort="100" velocity="100"/>
  </joint>

  <link name="finger_right_tip">

      <contact>
        <friction_anchor/>
        <stiffness value="30000.0"/>
        <damping value="1000.0"/>
        <lateral_friction value="1"/>
        <rolling_friction value="0.1"/>
        <contact_cfm value="0.0"/>
        <contact_erp value="1.0"/>
      </contact>

      <inertial>
          <mass value="0.1" />
          <origin xyz="0 0 0" />
      <inertia ixx="1.0" ixy="0.0" ixz="0.0"
               iyy="1.0" iyz="0.0" 
               izz="1.0" />
      </inertial>

      <visual>
          <!-- <origin xyz="-0.006 0 0.057" rpy="0 0 0" /> -->
          <geometry>
             <mesh filename="package://wsg50/digit.STL"/>
          </geometry>
          <material name="white">
            <color rgba="1. 1. 1. 1"/>
          </material>
      </visual>

      <collision>
          <!-- <origin xyz="-0.006 0 0.057" rpy="0 0 0" /> -->
          <geometry>
             <mesh filename="package://wsg50/digit.STL"/>
         </geometry>
     </collision>
  </link>


  <!-- ##################. Connect WSG50 to Sawyer ################## -->
  <!-- <joint name="arm_gripper_joint" type="fixed">
    <parent link="right_hand"/>
    <child link="gripper_base_link"/>
    <origin rpy="0.0 0.0 1.5708" xyz="0.0 0.0 0.0"/>
  </joint> -->



   <link name="panda_grasptarget">
    <inertial>
      <origin rpy="0 0 0" xyz="0 0 0"/>
       <mass value="0.0"/>
       <inertia ixx="0.1" ixy="0" ixz="0" iyy="0.1" iyz="0" izz="0.1"/>
    </inertial>
   </link>
   <joint name="panda_grasptarget_hand" type="fixed">
    <parent link="gripper_base_link"/>
    <child link="panda_grasptarget"/>
    <origin rpy="0 0 0" xyz="0 0 0.105"/>
  </joint>
  
</robot>
